<?xml version="1.0" ?>
<mujocoinclude>
    <body name="robot" pos="-0.8 0.0 0.0">
        <geom mesh="body-collision" pos="0 0 -0.28" rgba="0.15 0.15 0.15 1" type="mesh"/>
        <geom mesh="top" pos="0 0 -0.28" rgba="0.15 0.15 0.15 1" type="mesh"/>
        <geom pos="0.28 0 0.2295" quat="1 0.0 0 0" rgba="0.9 0.9 0.9 1" size="0.1 0.2295" type="cylinder"/>
        <geom mesh="ur5_base" pos="0.28 0 0.456" quat="0.681998 0 0 -0.731354" rgba="0.7 0.7 0.7 1" type="mesh"/>

        <joint axis="1 0 0" damping="0." name="robot_lin_x" pos="0 0 0" range="-100 100" type="slide"/>
        <joint axis="0 1 0" damping="0." name="robot_lin_y" pos="0 0 0" range="-100 100" type="slide"/>
        <joint axis="0 0 1" damping="0." name="robot_ang_z" pos="0 0 0" range="-100 100" type="hinge"/>

        <site name="base_site" pos="0.28 0. 0.456" quat="0.6819984 0 0 -0.7313537" type="sphere" size="0.005" rgba="1 1 1 1"/>

        <body name="base" pos="0 0 -0.2918">
            <geom conaffinity="1" contype="1" friction="0.4 0.4 0.4" mass="90" name="base" rgba="0. 0. 0. 1"
                  size="0.2 0.2 0.01425" type="box"/>
            <site name="ee_point_0" pos="0. 0. 0." rgba="1 0 1 0" size="0.005" type="sphere"/>
        </body>

        <body name="base_link" pos="0.28 0 0.545159" quat="0.681998 0.0 0.0 -0.731354">
            <inertial diaginertia="0.0102675 0.0102675 0.00666" mass="3.7" pos="0 0 0"/>
            <geom mesh="shoulder" rgba="0.7 0.7 0.7 1" type="mesh"/>
            <joint axis="0 0 1" limited="true" name="shoulder_pan_joint" pos="0 0 0" range="-3.14159 3.14159"/>

            <body name="shoulder_link" pos="0 0.13585 0" quat="0.707107 0.0 0.707107 0.0">
                <inertial diaginertia="0.226891 0.226891 0.0151074" mass="8.393" pos="0 0 0.28"/>
                <geom mesh="upperarm" rgba="0.7 0.7 0.7 1" type="mesh"/>
                <joint axis="0 1 0" limited="true" name="shoulder_lift_joint" pos="0 0 0" range="-3.14159 3.14159"/>

                <body name="elbow_link" pos="0 -0.1197 0.425" quat="1.0 0.0 0.0 0.0">
                    <inertial diaginertia="0.0494433 0.0494433 0.004095" mass="2.275" pos="0 0 0.25"/>
                    <geom mesh="forearm" rgba="0.7 0.7 0.7 1" type="mesh"/>
                    <joint axis="0 1 0" limited="true" name="elbow_joint" pos="0 0 0" range="-3.14159 3.14159"/>

                    <body name="wrist_1_link" pos="0 0 0.39225" quat="0.707107 0.0 0.707107 0.0">
                        <inertial diaginertia="0.21942 0.111173 0.111173" mass="1.219" pos="0 0 0"
                                  quat="0.5 0.5 -0.5 0.5"/>
                        <geom mesh="wrist1" rgba="0.7 0.7 0.7 1" type="mesh"/>
                        <joint axis="0 1 0" limited="true" name="wrist_1_joint" pos="0 0 0" range="-3.14159 3.14159"/>

                        <body name="wrist_2_link" pos="0 0.093 0" quat="1.0 0.0 0.0 0.0">
                            <inertial diaginertia="0.21942 0.111173 0.111173" mass="1.219" pos="0 0 0"
                                      quat="0.5 0.5 -0.5 0.5"/>
                            <geom friction="0.4 0.4 0.4" mesh="wrist2" rgba="0.7 0.7 0.7 1" type="mesh"/>
                            <joint axis="0 0 1" limited="true" name="wrist_2_joint" pos="0 0 0"
                                   range="-3.14159 3.14159"/>

                            <body name="wrist_3_link" pos="0 0 0.09465" quat="1.0 0.0 0.0 0.0">
                                <inertial diaginertia="0.033822 0.0171365 0.0171365" mass="0.1879" pos="0 0 0"
                                          quat="0.5 0.5 -0.5 0.5"/>
                                <geom friction="0.8 0.8 0.8" mesh="wrist3" rgba="0.7 0.7 0.7 1" type="mesh"/>
                                <joint axis="0 1 0" limited="true" name="wrist_3_joint" pos="0 0 0"
                                       range="-3.14159 3.14159"/>

                                <body name="ee_link" pos="0 0.0823 0"
                                      quat="0.50000015  -0.50000015 0.50000015  0.50000015">
                                    <geom conaffinity="3" contype="3" material="GriMat" mesh="kinova_robotiq_coupler"
                                          name="kinova_robotiq_coupler_mesh" pos="0 0 0.0466" type="mesh"/>
                                    <geom conaffinity="3" contype="3" material="GriMat" mesh="robotiq_85_base_link"
                                          name="robotiq_85_base_link_mesh" pos="0 0 0.0" quat="0.707107 0 -0.707107 0"
                                          type="mesh"/>

                                    <site name="ee_point_1" pos="0. 0. 0.1" quat="0.7071068 0 -0.7071068 0"
                                          rgba="1 1 1 0" size="0.005" type="sphere"/>
                                    <site name="ee_point_2" pos="0. 0. 0.12" rgba="1 0 1 0" size="0.005" type="sphere"/>

                                    <body name="right_driver" pos="0 -0.0306011 0.054904" quat="0.707107 0 -0.707107 0">
                                        <geom conaffinity="3" contype="3" mass="1.6" material="GriMat"
                                              mesh="robotiq_85_knuckle_link" name="right_driver_mesh" type="mesh"/>
                                        <joint axis="0 0 1" limited="true" name="joint7_1" range="0 0.872664626"
                                               type="hinge"/>

                                        <body name="right_coupler" pos="0 -0.0315 0">
                                            <geom conaffinity="3" contype="3" mass="1.6" material="GriMat"
                                                  mesh="robotiq_85_finger_link" name="right_coupler_mesh" type="mesh"/>
                                            <joint axis="0 0 1" limited="true" name="joint8_1" range="0 2.967059728"
                                                   type="hinge"/>

                                            <body name="right_follower_link" pos="0.0475 -0.006 0">
                                                <geom conaffinity="3" contype="3" mass="1.6" material="GriMat"
                                                      mesh="robotiq_85_finger_tip_link" name="right_follower_mesh"
                                                      pos="0.0025 0.021 0" type="mesh"/>
                                                <joint axis="0 0 1" limited="true" name="joint9_1" range="0 2.967059728"
                                                       type="hinge"/>
                                            </body>
                                        </body>
                                    </body>

                                    <body name="right_spring_link" pos="0.0016 -0.012 0.0614"
                                          quat="0.707107 0 -0.707107 0">
                                        <geom conaffinity="3" contype="3" mass="1.6" material="GriMat"
                                              mesh="robotiq_85_inner_knuckle_link" name="right_spring_mesh"
                                              pos="0 -0.0005 0.0016" type="mesh"/>
                                        <joint axis="0 0 1" limited="true" name="joint10_1" range="0 1" type="hinge"/>
                                    </body>

                                    <body name="left_driver" pos="0 0.0306011 0.054904" quat="0 0.707107 0 0.707107">
                                        <geom conaffinity="3" contype="3" mass="1.6" material="GriMat"
                                              mesh="robotiq_85_knuckle_link" name="left_driver_mesh" type="mesh"/>
                                        <joint axis="0 0 1" limited="true" name="joint7_2" range="0 0.872664626"
                                               type="hinge"/>
                                        <body name="left_coupler" pos="0 -0.0315 0">
                                            <geom conaffinity="3" contype="3" friction="0.2 0. 0.4" mass="1.6"
                                                  material="GriMat" mesh="robotiq_85_finger_link"
                                                  name="left_coupler_mesh" type="mesh"/>
                                            <joint axis="0 0 1" limited="true" name="joint8_2" range="0 2.967059728"
                                                   type="hinge"/>

                                            <body name="left_follower_link" pos="0.0475 -0.006 0">
                                                <geom conaffinity="3" contype="3" mass="1.6" material="GriMat"
                                                      mesh="robotiq_85_finger_tip_link" name="left_follower_mesh"
                                                      pos="0.0025 0.021 0" type="mesh"/>
                                                <joint axis="0 0 1" limited="true" name="joint9_2" range="0 2.967059728"
                                                       type="hinge"/>
                                            </body>
                                        </body>
                                    </body>

                                    <body name="left_spring_link" pos="0.0016 0.012 0.0614"
                                          quat="0 0.707107 0 0.707107">
                                        <geom conaffinity="3" contype="3" mass="1.6" material="GriMat"
                                              mesh="robotiq_85_inner_knuckle_link" name="left_spring_mesh"
                                              pos="0 0.0005 0.0016" type="mesh"/>
                                        <joint axis="0 0 1" limited="true" name="joint10_2" range="0 1" type="hinge"/>
                                    </body>
                                </body>
                            </body>
                        </body>
                    </body>
                </body>
            </body>
        </body>
    </body>
</mujocoinclude>