<mujocoinclude>
    <body name="robot" pos="0.0 0.0 0.01">
        <joint axis="1 0 0" name="robot_lin_x" pos="0 0 0" type="slide" range="-100 100"/>
        <joint axis="0 1 0" name="robot_lin_y" pos="0 0 0" type="slide" range="-100 100"/>
        <joint axis="0 0 1" name="robot_ang_z" pos="0 0 0" type="hinge" range="-100 100"/>

        <body name="base" pos="0 0 0.1425">
            <geom type="box" name="base" mass="100" friction="0.4 0.4 0.4" size="0.05 0.05 0.01425" rgba="0. 0. 0. 1" contype="1" conaffinity="1"/>
            <site name="ee_point_0" pos="0. 0. 0." type="sphere" size="0.005" rgba="1 0 1 0"/>
        </body>

        <body name="base_link" pos="0.0 0 0.105159" quat="-0.02425816  0.          0.         -0.9997057">
            <body name="wrist_2_link" pos="0 0.0 0" quat="0.70710678 0.         0.         0.70710678">
                <inertial pos="0 0 0" quat="0.5 0.5 -0.5 0.5" mass="5.219" diaginertia="0.21942 0.111173 0.111173"/>
                <geom type="mesh" rgba="0.7 0.7 0.7 1" contype="3" conaffinity="3" friction="0.4 0.4 0.4" mesh="wrist2"/>

                <body name="wrist_3_link" pos="0 0 0.09465" quat="0 0 -1 0">
                    <inertial pos="0 0 0" quat="0.5 0.5 -0.5 0.5" mass="5.1879" diaginertia="0.033822 0.0171365 0.0171365"/>
                    <geom type="mesh" rgba="0.7 0.7 0.7 1" contype="3" conaffinity="3" friction="0.8 0.8 0.8" mesh="wrist3"/>

                    <body name="ee_link" pos="0 0.0823 0" quat="0.50000015  -0.50000015 0.50000015  0.50000015">
                        <geom name="kinova_robotiq_coupler_mesh" contype="3" conaffinity="3" type="mesh" mesh="kinova_robotiq_coupler" pos="0 0 0.0466" material="GriMat"/>
                        <geom name="robotiq_85_base_link_mesh" contype="3" conaffinity="3" type="mesh" mesh="robotiq_85_base_link" pos="0 0 0.0" quat="0.707107 0 -0.707107 0" material="GriMat"/>

                        <site name="ee_point_1" pos="0. 0. 0.1" type="sphere" size="0.005" rgba="1 1 1 0"/>
                        <site name="ee_point_2" pos="0. 0. 0.12" type="sphere" size="0.005" rgba="1 0 1 0"/>

                        <body name="right_driver" pos="0 -0.0306011 0.054904" quat="0.707107 0 -0.707107 0">
                            <geom name="right_driver_mesh" contype="3" conaffinity="3" type="mesh" mass="1.6" mesh="robotiq_85_knuckle_link" material="GriMat"/>
                            <joint name="joint7_1" axis="0 0 1" type="hinge" limited="true" range="0 0.872664626"/>

                            <body name="right_coupler" pos="0 -0.0315 0">
                                <geom name="right_coupler_mesh" contype="3" conaffinity="3" type="mesh" mass="1.6" mesh="robotiq_85_finger_link" material="GriMat"/>
                                <joint name="joint8_1" axis="0 0 1" type="hinge" limited="true" range="0 2.967059728"/>

                                <body name="right_follower_link" pos="0.0475 -0.006 0">
                                    <geom name="right_follower_mesh" contype="3" conaffinity="3" mass="1.6" pos="0.0025 0.021 0" type="mesh" mesh="robotiq_85_finger_tip_link"
                                          material="GriMat"/>
                                    <joint name="joint9_1" axis="0 0 1" type="hinge" limited="true"
                                           range="0 2.967059728"/>
                                </body>
                            </body>
                        </body>

                        <body name="right_spring_link" pos="0.0016 -0.012 0.0614" quat="0.707107 0 -0.707107 0">
                            <geom name="right_spring_mesh" contype="3" conaffinity="3" type="mesh" mass="1.6" pos="0 -0.0005 0.0016" mesh="robotiq_85_inner_knuckle_link" material="GriMat"/>
                            <joint name="joint10_1" axis="0 0 1" type="hinge" limited="true" range="0 1"/>
                        </body>

                        <body name="left_driver" pos="0 0.0306011 0.054904" quat="0 0.707107 0 0.707107">
                            <geom name="left_driver_mesh" contype="3" conaffinity="3" type="mesh" mass="1.6" mesh="robotiq_85_knuckle_link" material="GriMat"/>
                            <joint name="joint7_2" axis="0 0 1" type="hinge" limited="true" range="0 0.872664626"/>
                            <body name="left_coupler" pos="0 -0.0315 0">
                                <geom name="left_coupler_mesh" contype="3" conaffinity="3" type="mesh" mass="1.6" friction="0.2 0. 0.4" mesh="robotiq_85_finger_link" material="GriMat"/>
                                <joint name="joint8_2" axis="0 0 1" type="hinge" limited="true" range="0 2.967059728"/>

                                <body name="left_follower_link" pos="0.0475 -0.006 0">
                                    <geom name="left_follower_mesh" contype="3" conaffinity="3" mass="1.6" pos="0.0025 0.021 0" type="mesh" mesh="robotiq_85_finger_tip_link"
                                          material="GriMat"/>
                                    <joint name="joint9_2" axis="0 0 1" type="hinge" limited="true"
                                           range="0 2.967059728"/>
                                </body>
                            </body>
                        </body>

                        <body name="left_spring_link" pos="0.0016 0.012 0.0614" quat="0 0.707107 0 0.707107">
                            <geom name="left_spring_mesh" contype="3" conaffinity="3" type="mesh" mass="1.6" pos="0 0.0005 0.0016" mesh="robotiq_85_inner_knuckle_link" material="GriMat"/>
                            <joint name="joint10_2" axis="0 0 1" type="hinge" limited="true" range="0 1"/>
                        </body>
                    </body>
                </body>
            </body>
        </body>
    </body>
</mujocoinclude>
